/usr/lib/python3/dist-packages/setuptools/command/install.py:34: SetuptoolsDeprecationWarning: setup.py install is deprecated. Use build and pip and other standards-based tools.
  warnings.warn(
/usr/lib/python3/dist-packages/setuptools/command/easy_install.py:146: EasyInstallDeprecationWarning: easy_install command is deprecated. Use build and pip and other standards-based tools.
  warnings.warn(
Traceback (most recent call last):
  File "/tmp/autopkgtest.Do379Q/autopkgtest_tmp/packages/fibpy/setup.py", line 5, in <module>
    setup(
  File "/usr/lib/python3/dist-packages/setuptools/__init__.py", line 87, in setup
    return distutils.core.setup(**attrs)
           ^^^^^^^^^^^^^^^^^^^^^^^^^^^^^
  File "/usr/lib/python3/dist-packages/setuptools/_distutils/core.py", line 185, in setup
    return run_commands(dist)
           ^^^^^^^^^^^^^^^^^^
  File "/usr/lib/python3/dist-packages/setuptools/_distutils/core.py", line 201, in run_commands
    dist.run_commands()
  File "/usr/lib/python3/dist-packages/setuptools/_distutils/dist.py", line 973, in run_commands
    self.run_command(cmd)
  File "/usr/lib/python3/dist-packages/setuptools/dist.py", line 1217, in run_command
    super().run_command(command)
  File "/usr/lib/python3/dist-packages/setuptools/_distutils/dist.py", line 992, in run_command
    cmd_obj.run()
  File "/usr/lib/python3/dist-packages/setuptools/command/install.py", line 74, in run
    self.do_egg_install()
  File "/usr/lib/python3/dist-packages/setuptools/command/install.py", line 117, in do_egg_install
    cmd.ensure_finalized()  # finalize before bdist_egg munges install cmd
    ^^^^^^^^^^^^^^^^^^^^^^
  File "/usr/lib/python3/dist-packages/setuptools/_distutils/cmd.py", line 109, in ensure_finalized
    self.finalize_options()
  File "/usr/lib/python3/dist-packages/setuptools/command/easy_install.py", line 231, in finalize_options
    self.config_vars = dict(sysconfig.get_config_vars())
                            ^^^^^^^^^
UnboundLocalError: cannot access local variable 'sysconfig' where it is not associated with a value
Error in sys.excepthook:
Traceback (most recent call last):
  File "/usr/lib/python3/dist-packages/apport_python_hook.py", line 63, in apport_excepthook
    from apport.fileutils import likely_packaged, get_recent_crashes
  File "/usr/lib/python3/dist-packages/apport/__init__.py", line 5, in <module>
    from apport.report import Report
  File "/usr/lib/python3/dist-packages/apport/report.py", line 30, in <module>
    import apport.fileutils
  File "/usr/lib/python3/dist-packages/apport/fileutils.py", line 23, in <module>
    from apport.packaging_impl import impl as packaging
  File "/usr/lib/python3/dist-packages/apport/packaging_impl.py", line 23, in <module>
    import apt
  File "/usr/lib/python3/dist-packages/apt/__init__.py", line 23, in <module>
    import apt_pkg
ModuleNotFoundError: No module named 'apt_pkg'

Original exception was:
Traceback (most recent call last):
  File "/tmp/autopkgtest.Do379Q/autopkgtest_tmp/packages/fibpy/setup.py", line 5, in <module>
    setup(
  File "/usr/lib/python3/dist-packages/setuptools/__init__.py", line 87, in setup
    return distutils.core.setup(**attrs)
           ^^^^^^^^^^^^^^^^^^^^^^^^^^^^^
  File "/usr/lib/python3/dist-packages/setuptools/_distutils/core.py", line 185, in setup
    return run_commands(dist)
           ^^^^^^^^^^^^^^^^^^
  File "/usr/lib/python3/dist-packages/setuptools/_distutils/core.py", line 201, in run_commands
    dist.run_commands()
  File "/usr/lib/python3/dist-packages/setuptools/_distutils/dist.py", line 973, in run_commands
    self.run_command(cmd)
  File "/usr/lib/python3/dist-packages/setuptools/dist.py", line 1217, in run_command
    super().run_command(command)
  File "/usr/lib/python3/dist-packages/setuptools/_distutils/dist.py", line 992, in run_command
    cmd_obj.run()
  File "/usr/lib/python3/dist-packages/setuptools/command/install.py", line 74, in run
    self.do_egg_install()
  File "/usr/lib/python3/dist-packages/setuptools/command/install.py", line 117, in do_egg_install
    cmd.ensure_finalized()  # finalize before bdist_egg munges install cmd
    ^^^^^^^^^^^^^^^^^^^^^^
  File "/usr/lib/python3/dist-packages/setuptools/_distutils/cmd.py", line 109, in ensure_finalized
    self.finalize_options()
  File "/usr/lib/python3/dist-packages/setuptools/command/easy_install.py", line 231, in finalize_options
    self.config_vars = dict(sysconfig.get_config_vars())
                            ^^^^^^^^^
UnboundLocalError: cannot access local variable 'sysconfig' where it is not associated with a value
/usr/bin/python3.11: No module named fibpy
/usr/lib/python3/dist-packages/setuptools/command/install.py:34: SetuptoolsDeprecationWarning: setup.py install is deprecated. Use build and pip and other standards-based tools.
  warnings.warn(
/usr/lib/python3/dist-packages/setuptools/command/easy_install.py:146: EasyInstallDeprecationWarning: easy_install command is deprecated. Use build and pip and other standards-based tools.
  warnings.warn(
Traceback (most recent call last):
  File "/tmp/autopkgtest.Do379Q/autopkgtest_tmp/packages/fibc/setup.py", line 5, in <module>
    setup(
  File "/usr/lib/python3/dist-packages/setuptools/__init__.py", line 87, in setup
    return distutils.core.setup(**attrs)
           ^^^^^^^^^^^^^^^^^^^^^^^^^^^^^
  File "/usr/lib/python3/dist-packages/setuptools/_distutils/core.py", line 185, in setup
    return run_commands(dist)
           ^^^^^^^^^^^^^^^^^^
  File "/usr/lib/python3/dist-packages/setuptools/_distutils/core.py", line 201, in run_commands
    dist.run_commands()
  File "/usr/lib/python3/dist-packages/setuptools/_distutils/dist.py", line 973, in run_commands
    self.run_command(cmd)
  File "/usr/lib/python3/dist-packages/setuptools/dist.py", line 1217, in run_command
    super().run_command(command)
  File "/usr/lib/python3/dist-packages/setuptools/_distutils/dist.py", line 992, in run_command
    cmd_obj.run()
  File "/usr/lib/python3/dist-packages/setuptools/command/install.py", line 74, in run
    self.do_egg_install()
  File "/usr/lib/python3/dist-packages/setuptools/command/install.py", line 117, in do_egg_install
    cmd.ensure_finalized()  # finalize before bdist_egg munges install cmd
    ^^^^^^^^^^^^^^^^^^^^^^
  File "/usr/lib/python3/dist-packages/setuptools/_distutils/cmd.py", line 109, in ensure_finalized
    self.finalize_options()
  File "/usr/lib/python3/dist-packages/setuptools/command/easy_install.py", line 231, in finalize_options
    self.config_vars = dict(sysconfig.get_config_vars())
                            ^^^^^^^^^
UnboundLocalError: cannot access local variable 'sysconfig' where it is not associated with a value
Error in sys.excepthook:
Traceback (most recent call last):
  File "/usr/lib/python3/dist-packages/apport_python_hook.py", line 63, in apport_excepthook
    from apport.fileutils import likely_packaged, get_recent_crashes
  File "/usr/lib/python3/dist-packages/apport/__init__.py", line 5, in <module>
    from apport.report import Report
  File "/usr/lib/python3/dist-packages/apport/report.py", line 30, in <module>
    import apport.fileutils
  File "/usr/lib/python3/dist-packages/apport/fileutils.py", line 23, in <module>
    from apport.packaging_impl import impl as packaging
  File "/usr/lib/python3/dist-packages/apport/packaging_impl.py", line 23, in <module>
    import apt
  File "/usr/lib/python3/dist-packages/apt/__init__.py", line 23, in <module>
    import apt_pkg
ModuleNotFoundError: No module named 'apt_pkg'

Original exception was:
Traceback (most recent call last):
  File "/tmp/autopkgtest.Do379Q/autopkgtest_tmp/packages/fibc/setup.py", line 5, in <module>
    setup(
  File "/usr/lib/python3/dist-packages/setuptools/__init__.py", line 87, in setup
    return distutils.core.setup(**attrs)
           ^^^^^^^^^^^^^^^^^^^^^^^^^^^^^
  File "/usr/lib/python3/dist-packages/setuptools/_distutils/core.py", line 185, in setup
    return run_commands(dist)
           ^^^^^^^^^^^^^^^^^^
  File "/usr/lib/python3/dist-packages/setuptools/_distutils/core.py", line 201, in run_commands
    dist.run_commands()
  File "/usr/lib/python3/dist-packages/setuptools/_distutils/dist.py", line 973, in run_commands
    self.run_command(cmd)
  File "/usr/lib/python3/dist-packages/setuptools/dist.py", line 1217, in run_command
    super().run_command(command)
  File "/usr/lib/python3/dist-packages/setuptools/_distutils/dist.py", line 992, in run_command
    cmd_obj.run()
  File "/usr/lib/python3/dist-packages/setuptools/command/install.py", line 74, in run
    self.do_egg_install()
  File "/usr/lib/python3/dist-packages/setuptools/command/install.py", line 117, in do_egg_install
    cmd.ensure_finalized()  # finalize before bdist_egg munges install cmd
    ^^^^^^^^^^^^^^^^^^^^^^
  File "/usr/lib/python3/dist-packages/setuptools/_distutils/cmd.py", line 109, in ensure_finalized
    self.finalize_options()
  File "/usr/lib/python3/dist-packages/setuptools/command/easy_install.py", line 231, in finalize_options
    self.config_vars = dict(sysconfig.get_config_vars())
                            ^^^^^^^^^
UnboundLocalError: cannot access local variable 'sysconfig' where it is not associated with a value
Traceback (most recent call last):
  File "<string>", line 1, in <module>
ModuleNotFoundError: No module named 'fibc'
Error in sys.excepthook:
Traceback (most recent call last):
  File "/usr/lib/python3/dist-packages/apport_python_hook.py", line 63, in apport_excepthook
    from apport.fileutils import likely_packaged, get_recent_crashes
  File "/usr/lib/python3/dist-packages/apport/__init__.py", line 5, in <module>
    from apport.report import Report
  File "/usr/lib/python3/dist-packages/apport/report.py", line 30, in <module>
    import apport.fileutils
  File "/usr/lib/python3/dist-packages/apport/fileutils.py", line 23, in <module>
    from apport.packaging_impl import impl as packaging
  File "/usr/lib/python3/dist-packages/apport/packaging_impl.py", line 23, in <module>
    import apt
  File "/usr/lib/python3/dist-packages/apt/__init__.py", line 23, in <module>
    import apt_pkg
ModuleNotFoundError: No module named 'apt_pkg'

Original exception was:
Traceback (most recent call last):
  File "<string>", line 1, in <module>
ModuleNotFoundError: No module named 'fibc'
/usr/lib/python3/dist-packages/setuptools/command/easy_install.py:146: EasyInstallDeprecationWarning: easy_install command is deprecated. Use build and pip and other standards-based tools.
  warnings.warn(
Traceback (most recent call last):
  File "/tmp/autopkgtest.Do379Q/autopkgtest_tmp/packages/fibpy/setup.py", line 5, in <module>
    setup(
  File "/usr/lib/python3/dist-packages/setuptools/__init__.py", line 87, in setup
    return distutils.core.setup(**attrs)
           ^^^^^^^^^^^^^^^^^^^^^^^^^^^^^
  File "/usr/lib/python3/dist-packages/setuptools/_distutils/core.py", line 185, in setup
    return run_commands(dist)
           ^^^^^^^^^^^^^^^^^^
  File "/usr/lib/python3/dist-packages/setuptools/_distutils/core.py", line 201, in run_commands
    dist.run_commands()
  File "/usr/lib/python3/dist-packages/setuptools/_distutils/dist.py", line 973, in run_commands
    self.run_command(cmd)
  File "/usr/lib/python3/dist-packages/setuptools/dist.py", line 1217, in run_command
    super().run_command(command)
  File "/usr/lib/python3/dist-packages/setuptools/_distutils/dist.py", line 991, in run_command
    cmd_obj.ensure_finalized()
  File "/usr/lib/python3/dist-packages/setuptools/_distutils/cmd.py", line 109, in ensure_finalized
    self.finalize_options()
  File "/usr/lib/python3/dist-packages/setuptools/command/develop.py", line 52, in finalize_options
    easy_install.finalize_options(self)
  File "/usr/lib/python3/dist-packages/setuptools/command/easy_install.py", line 231, in finalize_options
    self.config_vars = dict(sysconfig.get_config_vars())
                            ^^^^^^^^^
UnboundLocalError: cannot access local variable 'sysconfig' where it is not associated with a value
Error in sys.excepthook:
Traceback (most recent call last):
  File "/usr/lib/python3/dist-packages/apport_python_hook.py", line 63, in apport_excepthook
    from apport.fileutils import likely_packaged, get_recent_crashes
  File "/usr/lib/python3/dist-packages/apport/__init__.py", line 5, in <module>
    from apport.report import Report
  File "/usr/lib/python3/dist-packages/apport/report.py", line 30, in <module>
    import apport.fileutils
  File "/usr/lib/python3/dist-packages/apport/fileutils.py", line 23, in <module>
    from apport.packaging_impl import impl as packaging
  File "/usr/lib/python3/dist-packages/apport/packaging_impl.py", line 23, in <module>
    import apt
  File "/usr/lib/python3/dist-packages/apt/__init__.py", line 23, in <module>
    import apt_pkg
ModuleNotFoundError: No module named 'apt_pkg'

Original exception was:
Traceback (most recent call last):
  File "/tmp/autopkgtest.Do379Q/autopkgtest_tmp/packages/fibpy/setup.py", line 5, in <module>
    setup(
  File "/usr/lib/python3/dist-packages/setuptools/__init__.py", line 87, in setup
    return distutils.core.setup(**attrs)
           ^^^^^^^^^^^^^^^^^^^^^^^^^^^^^
  File "/usr/lib/python3/dist-packages/setuptools/_distutils/core.py", line 185, in setup
    return run_commands(dist)
           ^^^^^^^^^^^^^^^^^^
  File "/usr/lib/python3/dist-packages/setuptools/_distutils/core.py", line 201, in run_commands
    dist.run_commands()
  File "/usr/lib/python3/dist-packages/setuptools/_distutils/dist.py", line 973, in run_commands
    self.run_command(cmd)
  File "/usr/lib/python3/dist-packages/setuptools/dist.py", line 1217, in run_command
    super().run_command(command)
  File "/usr/lib/python3/dist-packages/setuptools/_distutils/dist.py", line 991, in run_command
    cmd_obj.ensure_finalized()
  File "/usr/lib/python3/dist-packages/setuptools/_distutils/cmd.py", line 109, in ensure_finalized
    self.finalize_options()
  File "/usr/lib/python3/dist-packages/setuptools/command/develop.py", line 52, in finalize_options
    easy_install.finalize_options(self)
  File "/usr/lib/python3/dist-packages/setuptools/command/easy_install.py", line 231, in finalize_options
    self.config_vars = dict(sysconfig.get_config_vars())
                            ^^^^^^^^^
UnboundLocalError: cannot access local variable 'sysconfig' where it is not associated with a value
/usr/bin/python3.11: No module named fibpy
Traceback (most recent call last):
  File "<frozen runpy>", line 198, in _run_module_as_main
  File "<frozen runpy>", line 88, in _run_code
  File "/usr/lib/python3/dist-packages/pip/__main__.py", line 16, in <module>
    from pip._internal.cli.main import main as _main  # isort:skip # noqa
    ^^^^^^^^^^^^^^^^^^^^^^^^^^^^^^^^^^^^^^^^^^^^^^^^
  File "/usr/lib/python3/dist-packages/pip/_internal/cli/main.py", line 10, in <module>
    from pip._internal.cli.autocompletion import autocomplete
  File "/usr/lib/python3/dist-packages/pip/_internal/cli/autocompletion.py", line 9, in <module>
    from pip._internal.cli.main_parser import create_main_parser
  File "/usr/lib/python3/dist-packages/pip/_internal/cli/main_parser.py", line 7, in <module>
    from pip._internal.cli import cmdoptions
  File "/usr/lib/python3/dist-packages/pip/_internal/cli/cmdoptions.py", line 19, in <module>
    from distutils.util import strtobool
ModuleNotFoundError: No module named 'distutils.util'
Error in sys.excepthook:
Traceback (most recent call last):
  File "/usr/lib/python3/dist-packages/apport_python_hook.py", line 63, in apport_excepthook
    from apport.fileutils import likely_packaged, get_recent_crashes
  File "/usr/lib/python3/dist-packages/apport/__init__.py", line 5, in <module>
    from apport.report import Report
  File "/usr/lib/python3/dist-packages/apport/report.py", line 30, in <module>
    import apport.fileutils
  File "/usr/lib/python3/dist-packages/apport/fileutils.py", line 23, in <module>
    from apport.packaging_impl import impl as packaging
  File "/usr/lib/python3/dist-packages/apport/packaging_impl.py", line 23, in <module>
    import apt
  File "/usr/lib/python3/dist-packages/apt/__init__.py", line 23, in <module>
    import apt_pkg
ModuleNotFoundError: No module named 'apt_pkg'

Original exception was:
Traceback (most recent call last):
  File "<frozen runpy>", line 198, in _run_module_as_main
  File "<frozen runpy>", line 88, in _run_code
  File "/usr/lib/python3/dist-packages/pip/__main__.py", line 16, in <module>
    from pip._internal.cli.main import main as _main  # isort:skip # noqa
    ^^^^^^^^^^^^^^^^^^^^^^^^^^^^^^^^^^^^^^^^^^^^^^^^
  File "/usr/lib/python3/dist-packages/pip/_internal/cli/main.py", line 10, in <module>
    from pip._internal.cli.autocompletion import autocomplete
  File "/usr/lib/python3/dist-packages/pip/_internal/cli/autocompletion.py", line 9, in <module>
    from pip._internal.cli.main_parser import create_main_parser
  File "/usr/lib/python3/dist-packages/pip/_internal/cli/main_parser.py", line 7, in <module>
    from pip._internal.cli import cmdoptions
  File "/usr/lib/python3/dist-packages/pip/_internal/cli/cmdoptions.py", line 19, in <module>
    from distutils.util import strtobool
ModuleNotFoundError: No module named 'distutils.util'
/usr/bin/python3.11: No module named fibpy
Traceback (most recent call last):
  File "<frozen runpy>", line 198, in _run_module_as_main
  File "<frozen runpy>", line 88, in _run_code
  File "/usr/lib/python3/dist-packages/pip/__main__.py", line 16, in <module>
    from pip._internal.cli.main import main as _main  # isort:skip # noqa
    ^^^^^^^^^^^^^^^^^^^^^^^^^^^^^^^^^^^^^^^^^^^^^^^^
  File "/usr/lib/python3/dist-packages/pip/_internal/cli/main.py", line 10, in <module>
    from pip._internal.cli.autocompletion import autocomplete
  File "/usr/lib/python3/dist-packages/pip/_internal/cli/autocompletion.py", line 9, in <module>
    from pip._internal.cli.main_parser import create_main_parser
  File "/usr/lib/python3/dist-packages/pip/_internal/cli/main_parser.py", line 7, in <module>
    from pip._internal.cli import cmdoptions
  File "/usr/lib/python3/dist-packages/pip/_internal/cli/cmdoptions.py", line 19, in <module>
    from distutils.util import strtobool
ModuleNotFoundError: No module named 'distutils.util'
Error in sys.excepthook:
Traceback (most recent call last):
  File "/usr/lib/python3/dist-packages/apport_python_hook.py", line 63, in apport_excepthook
    from apport.fileutils import likely_packaged, get_recent_crashes
  File "/usr/lib/python3/dist-packages/apport/__init__.py", line 5, in <module>
    from apport.report import Report
  File "/usr/lib/python3/dist-packages/apport/report.py", line 30, in <module>
    import apport.fileutils
  File "/usr/lib/python3/dist-packages/apport/fileutils.py", line 23, in <module>
    from apport.packaging_impl import impl as packaging
  File "/usr/lib/python3/dist-packages/apport/packaging_impl.py", line 23, in <module>
    import apt
  File "/usr/lib/python3/dist-packages/apt/__init__.py", line 23, in <module>
    import apt_pkg
ModuleNotFoundError: No module named 'apt_pkg'

Original exception was:
Traceback (most recent call last):
  File "<frozen runpy>", line 198, in _run_module_as_main
  File "<frozen runpy>", line 88, in _run_code
  File "/usr/lib/python3/dist-packages/pip/__main__.py", line 16, in <module>
    from pip._internal.cli.main import main as _main  # isort:skip # noqa
    ^^^^^^^^^^^^^^^^^^^^^^^^^^^^^^^^^^^^^^^^^^^^^^^^
  File "/usr/lib/python3/dist-packages/pip/_internal/cli/main.py", line 10, in <module>
    from pip._internal.cli.autocompletion import autocomplete
  File "/usr/lib/python3/dist-packages/pip/_internal/cli/autocompletion.py", line 9, in <module>
    from pip._internal.cli.main_parser import create_main_parser
  File "/usr/lib/python3/dist-packages/pip/_internal/cli/main_parser.py", line 7, in <module>
    from pip._internal.cli import cmdoptions
  File "/usr/lib/python3/dist-packages/pip/_internal/cli/cmdoptions.py", line 19, in <module>
    from distutils.util import strtobool
ModuleNotFoundError: No module named 'distutils.util'
/usr/bin/python3.11: No module named fibpy
/usr/lib/python3/dist-packages/setuptools/command/install.py:34: SetuptoolsDeprecationWarning: setup.py install is deprecated. Use build and pip and other standards-based tools.
  warnings.warn(
/usr/lib/python3/dist-packages/setuptools/command/easy_install.py:146: EasyInstallDeprecationWarning: easy_install command is deprecated. Use build and pip and other standards-based tools.
  warnings.warn(
Traceback (most recent call last):
  File "/tmp/autopkgtest.Do379Q/autopkgtest_tmp/packages/fibpy/setup.py", line 5, in <module>
    setup(
  File "/usr/lib/python3/dist-packages/setuptools/__init__.py", line 87, in setup
    return distutils.core.setup(**attrs)
           ^^^^^^^^^^^^^^^^^^^^^^^^^^^^^
  File "/usr/lib/python3/dist-packages/setuptools/_distutils/core.py", line 185, in setup
    return run_commands(dist)
           ^^^^^^^^^^^^^^^^^^
  File "/usr/lib/python3/dist-packages/setuptools/_distutils/core.py", line 201, in run_commands
    dist.run_commands()
  File "/usr/lib/python3/dist-packages/setuptools/_distutils/dist.py", line 973, in run_commands
    self.run_command(cmd)
  File "/usr/lib/python3/dist-packages/setuptools/dist.py", line 1217, in run_command
    super().run_command(command)
  File "/usr/lib/python3/dist-packages/setuptools/_distutils/dist.py", line 992, in run_command
    cmd_obj.run()
  File "/usr/lib/python3/dist-packages/setuptools/command/install.py", line 74, in run
    self.do_egg_install()
  File "/usr/lib/python3/dist-packages/setuptools/command/install.py", line 117, in do_egg_install
    cmd.ensure_finalized()  # finalize before bdist_egg munges install cmd
    ^^^^^^^^^^^^^^^^^^^^^^
  File "/usr/lib/python3/dist-packages/setuptools/_distutils/cmd.py", line 109, in ensure_finalized
    self.finalize_options()
  File "/usr/lib/python3/dist-packages/setuptools/command/easy_install.py", line 231, in finalize_options
    self.config_vars = dict(sysconfig.get_config_vars())
                            ^^^^^^^^^
UnboundLocalError: cannot access local variable 'sysconfig' where it is not associated with a value
Error in sys.excepthook:
Traceback (most recent call last):
  File "/usr/lib/python3/dist-packages/apport_python_hook.py", line 63, in apport_excepthook
    from apport.fileutils import likely_packaged, get_recent_crashes
  File "/usr/lib/python3/dist-packages/apport/__init__.py", line 5, in <module>
    from apport.report import Report
  File "/usr/lib/python3/dist-packages/apport/report.py", line 30, in <module>
    import apport.fileutils
  File "/usr/lib/python3/dist-packages/apport/fileutils.py", line 23, in <module>
    from apport.packaging_impl import impl as packaging
  File "/usr/lib/python3/dist-packages/apport/packaging_impl.py", line 23, in <module>
    import apt
  File "/usr/lib/python3/dist-packages/apt/__init__.py", line 23, in <module>
    import apt_pkg
ModuleNotFoundError: No module named 'apt_pkg'

Original exception was:
Traceback (most recent call last):
  File "/tmp/autopkgtest.Do379Q/autopkgtest_tmp/packages/fibpy/setup.py", line 5, in <module>
    setup(
  File "/usr/lib/python3/dist-packages/setuptools/__init__.py", line 87, in setup
    return distutils.core.setup(**attrs)
           ^^^^^^^^^^^^^^^^^^^^^^^^^^^^^
  File "/usr/lib/python3/dist-packages/setuptools/_distutils/core.py", line 185, in setup
    return run_commands(dist)
           ^^^^^^^^^^^^^^^^^^
  File "/usr/lib/python3/dist-packages/setuptools/_distutils/core.py", line 201, in run_commands
    dist.run_commands()
  File "/usr/lib/python3/dist-packages/setuptools/_distutils/dist.py", line 973, in run_commands
    self.run_command(cmd)
  File "/usr/lib/python3/dist-packages/setuptools/dist.py", line 1217, in run_command
    super().run_command(command)
  File "/usr/lib/python3/dist-packages/setuptools/_distutils/dist.py", line 992, in run_command
    cmd_obj.run()
  File "/usr/lib/python3/dist-packages/setuptools/command/install.py", line 74, in run
    self.do_egg_install()
  File "/usr/lib/python3/dist-packages/setuptools/command/install.py", line 117, in do_egg_install
    cmd.ensure_finalized()  # finalize before bdist_egg munges install cmd
    ^^^^^^^^^^^^^^^^^^^^^^
  File "/usr/lib/python3/dist-packages/setuptools/_distutils/cmd.py", line 109, in ensure_finalized
    self.finalize_options()
  File "/usr/lib/python3/dist-packages/setuptools/command/easy_install.py", line 231, in finalize_options
    self.config_vars = dict(sysconfig.get_config_vars())
                            ^^^^^^^^^
UnboundLocalError: cannot access local variable 'sysconfig' where it is not associated with a value
/usr/bin/python3.11: No module named fibpy
